Error while getting Updates: urllib3 HTTPError HTTPSConnectionPool(host='api.telegram.org', port=443): Max retries exceeded with url: /bot5396659125:AAGCO4gHk2qm0RY2trx7u6pO23OpwAO4hg0/getUpdates (Caused by NewConnectionError('<telegram.vendor.ptb_urllib3.urllib3.connection.VerifiedHTTPSConnection object at 0x7fd5ca1eda30>: Failed to establish a new connection: [Errno -3] Temporary failure in name resolution'))
No error handlers are registered, logging exception.
Traceback (most recent call last):
  File "/home/nathan/Documents/saneora_env/lib/python3.9/site-packages/telegram/vendor/ptb_urllib3/urllib3/connection.py", line 140, in _new_conn
    conn = connection.create_connection(
  File "/home/nathan/Documents/saneora_env/lib/python3.9/site-packages/telegram/vendor/ptb_urllib3/urllib3/util/connection.py", line 60, in create_connection
    for res in socket.getaddrinfo(host, port, family, socket.SOCK_STREAM):
  File "/usr/lib/python3.9/socket.py", line 953, in getaddrinfo
    for res in _socket.getaddrinfo(host, port, family, type, proto, flags):
socket.gaierror: [Errno -3] Temporary failure in name resolution

During handling of the above exception, another exception occurred:

Traceback (most recent call last):
  File "/home/nathan/Documents/saneora_env/lib/python3.9/site-packages/telegram/vendor/ptb_urllib3/urllib3/connectionpool.py", line 614, in urlopen
    httplib_response = self._make_request(conn, method, url,
  File "/home/nathan/Documents/saneora_env/lib/python3.9/site-packages/telegram/vendor/ptb_urllib3/urllib3/connectionpool.py", line 360, in _make_request
    self._validate_conn(conn)
  File "/home/nathan/Documents/saneora_env/lib/python3.9/site-packages/telegram/vendor/ptb_urllib3/urllib3/connectionpool.py", line 857, in _validate_conn
    super(HTTPSConnectionPool, self)._validate_conn(conn)
  File "/home/nathan/Documents/saneora_env/lib/python3.9/site-packages/telegram/vendor/ptb_urllib3/urllib3/connectionpool.py", line 289, in _validate_conn
    conn.connect()
  File "/home/nathan/Documents/saneora_env/lib/python3.9/site-packages/telegram/vendor/ptb_urllib3/urllib3/connection.py", line 284, in connect
    conn = self._new_conn()
  File "/home/nathan/Documents/saneora_env/lib/python3.9/site-packages/telegram/vendor/ptb_urllib3/urllib3/connection.py", line 149, in _new_conn
    raise NewConnectionError(
telegram.vendor.ptb_urllib3.urllib3.exceptions.NewConnectionError: <telegram.vendor.ptb_urllib3.urllib3.connection.VerifiedHTTPSConnection object at 0x7fd5ca1eda30>: Failed to establish a new connection: [Errno -3] Temporary failure in name resolution

During handling of the above exception, another exception occurred:

Traceback (most recent call last):
  File "/home/nathan/Documents/saneora_env/lib/python3.9/site-packages/telegram/utils/request.py", line 259, in _request_wrapper
    resp = self._con_pool.request(*args, **kwargs)
  File "/home/nathan/Documents/saneora_env/lib/python3.9/site-packages/telegram/vendor/ptb_urllib3/urllib3/request.py", line 68, in request
    return self.request_encode_body(method, url, fields=fields,
  File "/home/nathan/Documents/saneora_env/lib/python3.9/site-packages/telegram/vendor/ptb_urllib3/urllib3/request.py", line 148, in request_encode_body
    return self.urlopen(method, url, **extra_kw)
  File "/home/nathan/Documents/saneora_env/lib/python3.9/site-packages/telegram/vendor/ptb_urllib3/urllib3/poolmanager.py", line 244, in urlopen
    response = conn.urlopen(method, u.request_uri, **kw)
  File "/home/nathan/Documents/saneora_env/lib/python3.9/site-packages/telegram/vendor/ptb_urllib3/urllib3/connectionpool.py", line 691, in urlopen
    return self.urlopen(method, url, body, headers, retries,
  File "/home/nathan/Documents/saneora_env/lib/python3.9/site-packages/telegram/vendor/ptb_urllib3/urllib3/connectionpool.py", line 691, in urlopen
    return self.urlopen(method, url, body, headers, retries,
  File "/home/nathan/Documents/saneora_env/lib/python3.9/site-packages/telegram/vendor/ptb_urllib3/urllib3/connectionpool.py", line 691, in urlopen
    return self.urlopen(method, url, body, headers, retries,
  File "/home/nathan/Documents/saneora_env/lib/python3.9/site-packages/telegram/vendor/ptb_urllib3/urllib3/connectionpool.py", line 665, in urlopen
    retries = retries.increment(method, url, error=e, _pool=self,
  File "/home/nathan/Documents/saneora_env/lib/python3.9/site-packages/telegram/vendor/ptb_urllib3/urllib3/util/retry.py", line 376, in increment
    raise MaxRetryError(_pool, url, error or ResponseError(cause))
telegram.vendor.ptb_urllib3.urllib3.exceptions.MaxRetryError: HTTPSConnectionPool(host='api.telegram.org', port=443): Max retries exceeded with url: /bot5396659125:AAGCO4gHk2qm0RY2trx7u6pO23OpwAO4hg0/getUpdates (Caused by NewConnectionError('<telegram.vendor.ptb_urllib3.urllib3.connection.VerifiedHTTPSConnection object at 0x7fd5ca1eda30>: Failed to establish a new connection: [Errno -3] Temporary failure in name resolution'))

The above exception was the direct cause of the following exception:

Traceback (most recent call last):
  File "/home/nathan/Documents/saneora_env/lib/python3.9/site-packages/telegram/ext/updater.py", line 646, in _network_loop_retry
    if not action_cb():
  File "/home/nathan/Documents/saneora_env/lib/python3.9/site-packages/telegram/ext/updater.py", line 597, in polling_action_cb
    updates = self.bot.get_updates(
  File "/home/nathan/Documents/saneora_env/lib/python3.9/site-packages/telegram/ext/extbot.py", line 224, in get_updates
    updates = super().get_updates(
  File "/home/nathan/Documents/saneora_env/lib/python3.9/site-packages/telegram/bot.py", line 130, in decorator
    result = func(*args, **kwargs)
  File "/home/nathan/Documents/saneora_env/lib/python3.9/site-packages/telegram/bot.py", line 3054, in get_updates
    self._post(
  File "/home/nathan/Documents/saneora_env/lib/python3.9/site-packages/telegram/bot.py", line 295, in _post
    return self.request.post(
  File "/home/nathan/Documents/saneora_env/lib/python3.9/site-packages/telegram/utils/request.py", line 361, in post
    result = self._request_wrapper(
  File "/home/nathan/Documents/saneora_env/lib/python3.9/site-packages/telegram/utils/request.py", line 265, in _request_wrapper
    raise NetworkError(f'urllib3 HTTPError {error}') from error
telegram.error.NetworkError: urllib3 HTTPError HTTPSConnectionPool(host='api.telegram.org', port=443): Max retries exceeded with url: /bot5396659125:AAGCO4gHk2qm0RY2trx7u6pO23OpwAO4hg0/getUpdates (Caused by NewConnectionError('<telegram.vendor.ptb_urllib3.urllib3.connection.VerifiedHTTPSConnection object at 0x7fd5ca1eda30>: Failed to establish a new connection: [Errno -3] Temporary failure in name resolution'))
Error while getting Updates: urllib3 HTTPError HTTPSConnectionPool(host='api.telegram.org', port=443): Max retries exceeded with url: /bot5396659125:AAGCO4gHk2qm0RY2trx7u6pO23OpwAO4hg0/getUpdates (Caused by NewConnectionError('<telegram.vendor.ptb_urllib3.urllib3.connection.VerifiedHTTPSConnection object at 0x7fd5c993ba00>: Failed to establish a new connection: [Errno -3] Temporary failure in name resolution'))
No error handlers are registered, logging exception.
Traceback (most recent call last):
  File "/home/nathan/Documents/saneora_env/lib/python3.9/site-packages/telegram/vendor/ptb_urllib3/urllib3/connection.py", line 140, in _new_conn
    conn = connection.create_connection(
  File "/home/nathan/Documents/saneora_env/lib/python3.9/site-packages/telegram/vendor/ptb_urllib3/urllib3/util/connection.py", line 60, in create_connection
    for res in socket.getaddrinfo(host, port, family, socket.SOCK_STREAM):
  File "/usr/lib/python3.9/socket.py", line 953, in getaddrinfo
    for res in _socket.getaddrinfo(host, port, family, type, proto, flags):
socket.gaierror: [Errno -3] Temporary failure in name resolution

During handling of the above exception, another exception occurred:

Traceback (most recent call last):
  File "/home/nathan/Documents/saneora_env/lib/python3.9/site-packages/telegram/vendor/ptb_urllib3/urllib3/connectionpool.py", line 614, in urlopen
    httplib_response = self._make_request(conn, method, url,
  File "/home/nathan/Documents/saneora_env/lib/python3.9/site-packages/telegram/vendor/ptb_urllib3/urllib3/connectionpool.py", line 360, in _make_request
    self._validate_conn(conn)
  File "/home/nathan/Documents/saneora_env/lib/python3.9/site-packages/telegram/vendor/ptb_urllib3/urllib3/connectionpool.py", line 857, in _validate_conn
    super(HTTPSConnectionPool, self)._validate_conn(conn)
  File "/home/nathan/Documents/saneora_env/lib/python3.9/site-packages/telegram/vendor/ptb_urllib3/urllib3/connectionpool.py", line 289, in _validate_conn
    conn.connect()
  File "/home/nathan/Documents/saneora_env/lib/python3.9/site-packages/telegram/vendor/ptb_urllib3/urllib3/connection.py", line 284, in connect
    conn = self._new_conn()
  File "/home/nathan/Documents/saneora_env/lib/python3.9/site-packages/telegram/vendor/ptb_urllib3/urllib3/connection.py", line 149, in _new_conn
    raise NewConnectionError(
telegram.vendor.ptb_urllib3.urllib3.exceptions.NewConnectionError: <telegram.vendor.ptb_urllib3.urllib3.connection.VerifiedHTTPSConnection object at 0x7fd5c993ba00>: Failed to establish a new connection: [Errno -3] Temporary failure in name resolution

During handling of the above exception, another exception occurred:

Traceback (most recent call last):
  File "/home/nathan/Documents/saneora_env/lib/python3.9/site-packages/telegram/utils/request.py", line 259, in _request_wrapper
    resp = self._con_pool.request(*args, **kwargs)
  File "/home/nathan/Documents/saneora_env/lib/python3.9/site-packages/telegram/vendor/ptb_urllib3/urllib3/request.py", line 68, in request
    return self.request_encode_body(method, url, fields=fields,
  File "/home/nathan/Documents/saneora_env/lib/python3.9/site-packages/telegram/vendor/ptb_urllib3/urllib3/request.py", line 148, in request_encode_body
    return self.urlopen(method, url, **extra_kw)
  File "/home/nathan/Documents/saneora_env/lib/python3.9/site-packages/telegram/vendor/ptb_urllib3/urllib3/poolmanager.py", line 244, in urlopen
    response = conn.urlopen(method, u.request_uri, **kw)
  File "/home/nathan/Documents/saneora_env/lib/python3.9/site-packages/telegram/vendor/ptb_urllib3/urllib3/connectionpool.py", line 691, in urlopen
    return self.urlopen(method, url, body, headers, retries,
  File "/home/nathan/Documents/saneora_env/lib/python3.9/site-packages/telegram/vendor/ptb_urllib3/urllib3/connectionpool.py", line 691, in urlopen
    return self.urlopen(method, url, body, headers, retries,
  File "/home/nathan/Documents/saneora_env/lib/python3.9/site-packages/telegram/vendor/ptb_urllib3/urllib3/connectionpool.py", line 691, in urlopen
    return self.urlopen(method, url, body, headers, retries,
  File "/home/nathan/Documents/saneora_env/lib/python3.9/site-packages/telegram/vendor/ptb_urllib3/urllib3/connectionpool.py", line 665, in urlopen
    retries = retries.increment(method, url, error=e, _pool=self,
  File "/home/nathan/Documents/saneora_env/lib/python3.9/site-packages/telegram/vendor/ptb_urllib3/urllib3/util/retry.py", line 376, in increment
    raise MaxRetryError(_pool, url, error or ResponseError(cause))
telegram.vendor.ptb_urllib3.urllib3.exceptions.MaxRetryError: HTTPSConnectionPool(host='api.telegram.org', port=443): Max retries exceeded with url: /bot5396659125:AAGCO4gHk2qm0RY2trx7u6pO23OpwAO4hg0/getUpdates (Caused by NewConnectionError('<telegram.vendor.ptb_urllib3.urllib3.connection.VerifiedHTTPSConnection object at 0x7fd5c993ba00>: Failed to establish a new connection: [Errno -3] Temporary failure in name resolution'))

The above exception was the direct cause of the following exception:

Traceback (most recent call last):
  File "/home/nathan/Documents/saneora_env/lib/python3.9/site-packages/telegram/ext/updater.py", line 646, in _network_loop_retry
    if not action_cb():
  File "/home/nathan/Documents/saneora_env/lib/python3.9/site-packages/telegram/ext/updater.py", line 597, in polling_action_cb
    updates = self.bot.get_updates(
  File "/home/nathan/Documents/saneora_env/lib/python3.9/site-packages/telegram/ext/extbot.py", line 224, in get_updates
    updates = super().get_updates(
  File "/home/nathan/Documents/saneora_env/lib/python3.9/site-packages/telegram/bot.py", line 130, in decorator
    result = func(*args, **kwargs)
  File "/home/nathan/Documents/saneora_env/lib/python3.9/site-packages/telegram/bot.py", line 3054, in get_updates
    self._post(
  File "/home/nathan/Documents/saneora_env/lib/python3.9/site-packages/telegram/bot.py", line 295, in _post
    return self.request.post(
  File "/home/nathan/Documents/saneora_env/lib/python3.9/site-packages/telegram/utils/request.py", line 361, in post
    result = self._request_wrapper(
  File "/home/nathan/Documents/saneora_env/lib/python3.9/site-packages/telegram/utils/request.py", line 265, in _request_wrapper
    raise NetworkError(f'urllib3 HTTPError {error}') from error
telegram.error.NetworkError: urllib3 HTTPError HTTPSConnectionPool(host='api.telegram.org', port=443): Max retries exceeded with url: /bot5396659125:AAGCO4gHk2qm0RY2trx7u6pO23OpwAO4hg0/getUpdates (Caused by NewConnectionError('<telegram.vendor.ptb_urllib3.urllib3.connection.VerifiedHTTPSConnection object at 0x7fd5c993ba00>: Failed to establish a new connection: [Errno -3] Temporary failure in name resolution'))
Error while getting Updates: urllib3 HTTPError HTTPSConnectionPool(host='api.telegram.org', port=443): Max retries exceeded with url: /bot5396659125:AAGCO4gHk2qm0RY2trx7u6pO23OpwAO4hg0/getUpdates (Caused by NewConnectionError('<telegram.vendor.ptb_urllib3.urllib3.connection.VerifiedHTTPSConnection object at 0x7fd5c993be50>: Failed to establish a new connection: [Errno -3] Temporary failure in name resolution'))
No error handlers are registered, logging exception.
Traceback (most recent call last):
  File "/home/nathan/Documents/saneora_env/lib/python3.9/site-packages/telegram/vendor/ptb_urllib3/urllib3/connection.py", line 140, in _new_conn
    conn = connection.create_connection(
  File "/home/nathan/Documents/saneora_env/lib/python3.9/site-packages/telegram/vendor/ptb_urllib3/urllib3/util/connection.py", line 60, in create_connection
    for res in socket.getaddrinfo(host, port, family, socket.SOCK_STREAM):
  File "/usr/lib/python3.9/socket.py", line 953, in getaddrinfo
    for res in _socket.getaddrinfo(host, port, family, type, proto, flags):
socket.gaierror: [Errno -3] Temporary failure in name resolution

During handling of the above exception, another exception occurred:

Traceback (most recent call last):
  File "/home/nathan/Documents/saneora_env/lib/python3.9/site-packages/telegram/vendor/ptb_urllib3/urllib3/connectionpool.py", line 614, in urlopen
    httplib_response = self._make_request(conn, method, url,
  File "/home/nathan/Documents/saneora_env/lib/python3.9/site-packages/telegram/vendor/ptb_urllib3/urllib3/connectionpool.py", line 360, in _make_request
    self._validate_conn(conn)
  File "/home/nathan/Documents/saneora_env/lib/python3.9/site-packages/telegram/vendor/ptb_urllib3/urllib3/connectionpool.py", line 857, in _validate_conn
    super(HTTPSConnectionPool, self)._validate_conn(conn)
  File "/home/nathan/Documents/saneora_env/lib/python3.9/site-packages/telegram/vendor/ptb_urllib3/urllib3/connectionpool.py", line 289, in _validate_conn
    conn.connect()
  File "/home/nathan/Documents/saneora_env/lib/python3.9/site-packages/telegram/vendor/ptb_urllib3/urllib3/connection.py", line 284, in connect
    conn = self._new_conn()
  File "/home/nathan/Documents/saneora_env/lib/python3.9/site-packages/telegram/vendor/ptb_urllib3/urllib3/connection.py", line 149, in _new_conn
    raise NewConnectionError(
telegram.vendor.ptb_urllib3.urllib3.exceptions.NewConnectionError: <telegram.vendor.ptb_urllib3.urllib3.connection.VerifiedHTTPSConnection object at 0x7fd5c993be50>: Failed to establish a new connection: [Errno -3] Temporary failure in name resolution

During handling of the above exception, another exception occurred:

Traceback (most recent call last):
  File "/home/nathan/Documents/saneora_env/lib/python3.9/site-packages/telegram/utils/request.py", line 259, in _request_wrapper
    resp = self._con_pool.request(*args, **kwargs)
  File "/home/nathan/Documents/saneora_env/lib/python3.9/site-packages/telegram/vendor/ptb_urllib3/urllib3/request.py", line 68, in request
    return self.request_encode_body(method, url, fields=fields,
  File "/home/nathan/Documents/saneora_env/lib/python3.9/site-packages/telegram/vendor/ptb_urllib3/urllib3/request.py", line 148, in request_encode_body
    return self.urlopen(method, url, **extra_kw)
  File "/home/nathan/Documents/saneora_env/lib/python3.9/site-packages/telegram/vendor/ptb_urllib3/urllib3/poolmanager.py", line 244, in urlopen
    response = conn.urlopen(method, u.request_uri, **kw)
  File "/home/nathan/Documents/saneora_env/lib/python3.9/site-packages/telegram/vendor/ptb_urllib3/urllib3/connectionpool.py", line 691, in urlopen
    return self.urlopen(method, url, body, headers, retries,
  File "/home/nathan/Documents/saneora_env/lib/python3.9/site-packages/telegram/vendor/ptb_urllib3/urllib3/connectionpool.py", line 691, in urlopen
    return self.urlopen(method, url, body, headers, retries,
  File "/home/nathan/Documents/saneora_env/lib/python3.9/site-packages/telegram/vendor/ptb_urllib3/urllib3/connectionpool.py", line 691, in urlopen
    return self.urlopen(method, url, body, headers, retries,
  File "/home/nathan/Documents/saneora_env/lib/python3.9/site-packages/telegram/vendor/ptb_urllib3/urllib3/connectionpool.py", line 665, in urlopen
    retries = retries.increment(method, url, error=e, _pool=self,
  File "/home/nathan/Documents/saneora_env/lib/python3.9/site-packages/telegram/vendor/ptb_urllib3/urllib3/util/retry.py", line 376, in increment
    raise MaxRetryError(_pool, url, error or ResponseError(cause))
telegram.vendor.ptb_urllib3.urllib3.exceptions.MaxRetryError: HTTPSConnectionPool(host='api.telegram.org', port=443): Max retries exceeded with url: /bot5396659125:AAGCO4gHk2qm0RY2trx7u6pO23OpwAO4hg0/getUpdates (Caused by NewConnectionError('<telegram.vendor.ptb_urllib3.urllib3.connection.VerifiedHTTPSConnection object at 0x7fd5c993be50>: Failed to establish a new connection: [Errno -3] Temporary failure in name resolution'))

The above exception was the direct cause of the following exception:

Traceback (most recent call last):
  File "/home/nathan/Documents/saneora_env/lib/python3.9/site-packages/telegram/ext/updater.py", line 646, in _network_loop_retry
    if not action_cb():
  File "/home/nathan/Documents/saneora_env/lib/python3.9/site-packages/telegram/ext/updater.py", line 597, in polling_action_cb
    updates = self.bot.get_updates(
  File "/home/nathan/Documents/saneora_env/lib/python3.9/site-packages/telegram/ext/extbot.py", line 224, in get_updates
    updates = super().get_updates(
  File "/home/nathan/Documents/saneora_env/lib/python3.9/site-packages/telegram/bot.py", line 130, in decorator
    result = func(*args, **kwargs)
  File "/home/nathan/Documents/saneora_env/lib/python3.9/site-packages/telegram/bot.py", line 3054, in get_updates
    self._post(
  File "/home/nathan/Documents/saneora_env/lib/python3.9/site-packages/telegram/bot.py", line 295, in _post
    return self.request.post(
  File "/home/nathan/Documents/saneora_env/lib/python3.9/site-packages/telegram/utils/request.py", line 361, in post
    result = self._request_wrapper(
  File "/home/nathan/Documents/saneora_env/lib/python3.9/site-packages/telegram/utils/request.py", line 265, in _request_wrapper
    raise NetworkError(f'urllib3 HTTPError {error}') from error
telegram.error.NetworkError: urllib3 HTTPError HTTPSConnectionPool(host='api.telegram.org', port=443): Max retries exceeded with url: /bot5396659125:AAGCO4gHk2qm0RY2trx7u6pO23OpwAO4hg0/getUpdates (Caused by NewConnectionError('<telegram.vendor.ptb_urllib3.urllib3.connection.VerifiedHTTPSConnection object at 0x7fd5c993be50>: Failed to establish a new connection: [Errno -3] Temporary failure in name resolution'))
Error while getting Updates: urllib3 HTTPError HTTPSConnectionPool(host='api.telegram.org', port=443): Max retries exceeded with url: /bot5396659125:AAGCO4gHk2qm0RY2trx7u6pO23OpwAO4hg0/getUpdates (Caused by NewConnectionError('<telegram.vendor.ptb_urllib3.urllib3.connection.VerifiedHTTPSConnection object at 0x7fd5c804a2e0>: Failed to establish a new connection: [Errno -3] Temporary failure in name resolution'))
No error handlers are registered, logging exception.
Traceback (most recent call last):
  File "/home/nathan/Documents/saneora_env/lib/python3.9/site-packages/telegram/vendor/ptb_urllib3/urllib3/connection.py", line 140, in _new_conn
    conn = connection.create_connection(
  File "/home/nathan/Documents/saneora_env/lib/python3.9/site-packages/telegram/vendor/ptb_urllib3/urllib3/util/connection.py", line 60, in create_connection
    for res in socket.getaddrinfo(host, port, family, socket.SOCK_STREAM):
  File "/usr/lib/python3.9/socket.py", line 953, in getaddrinfo
    for res in _socket.getaddrinfo(host, port, family, type, proto, flags):
socket.gaierror: [Errno -3] Temporary failure in name resolution

During handling of the above exception, another exception occurred:

Traceback (most recent call last):
  File "/home/nathan/Documents/saneora_env/lib/python3.9/site-packages/telegram/vendor/ptb_urllib3/urllib3/connectionpool.py", line 614, in urlopen
    httplib_response = self._make_request(conn, method, url,
  File "/home/nathan/Documents/saneora_env/lib/python3.9/site-packages/telegram/vendor/ptb_urllib3/urllib3/connectionpool.py", line 360, in _make_request
    self._validate_conn(conn)
  File "/home/nathan/Documents/saneora_env/lib/python3.9/site-packages/telegram/vendor/ptb_urllib3/urllib3/connectionpool.py", line 857, in _validate_conn
    super(HTTPSConnectionPool, self)._validate_conn(conn)
  File "/home/nathan/Documents/saneora_env/lib/python3.9/site-packages/telegram/vendor/ptb_urllib3/urllib3/connectionpool.py", line 289, in _validate_conn
    conn.connect()
  File "/home/nathan/Documents/saneora_env/lib/python3.9/site-packages/telegram/vendor/ptb_urllib3/urllib3/connection.py", line 284, in connect
    conn = self._new_conn()
  File "/home/nathan/Documents/saneora_env/lib/python3.9/site-packages/telegram/vendor/ptb_urllib3/urllib3/connection.py", line 149, in _new_conn
    raise NewConnectionError(
telegram.vendor.ptb_urllib3.urllib3.exceptions.NewConnectionError: <telegram.vendor.ptb_urllib3.urllib3.connection.VerifiedHTTPSConnection object at 0x7fd5c804a2e0>: Failed to establish a new connection: [Errno -3] Temporary failure in name resolution

During handling of the above exception, another exception occurred:

Traceback (most recent call last):
  File "/home/nathan/Documents/saneora_env/lib/python3.9/site-packages/telegram/utils/request.py", line 259, in _request_wrapper
    resp = self._con_pool.request(*args, **kwargs)
  File "/home/nathan/Documents/saneora_env/lib/python3.9/site-packages/telegram/vendor/ptb_urllib3/urllib3/request.py", line 68, in request
    return self.request_encode_body(method, url, fields=fields,
  File "/home/nathan/Documents/saneora_env/lib/python3.9/site-packages/telegram/vendor/ptb_urllib3/urllib3/request.py", line 148, in request_encode_body
    return self.urlopen(method, url, **extra_kw)
  File "/home/nathan/Documents/saneora_env/lib/python3.9/site-packages/telegram/vendor/ptb_urllib3/urllib3/poolmanager.py", line 244, in urlopen
    response = conn.urlopen(method, u.request_uri, **kw)
  File "/home/nathan/Documents/saneora_env/lib/python3.9/site-packages/telegram/vendor/ptb_urllib3/urllib3/connectionpool.py", line 691, in urlopen
    return self.urlopen(method, url, body, headers, retries,
  File "/home/nathan/Documents/saneora_env/lib/python3.9/site-packages/telegram/vendor/ptb_urllib3/urllib3/connectionpool.py", line 691, in urlopen
    return self.urlopen(method, url, body, headers, retries,
  File "/home/nathan/Documents/saneora_env/lib/python3.9/site-packages/telegram/vendor/ptb_urllib3/urllib3/connectionpool.py", line 691, in urlopen
    return self.urlopen(method, url, body, headers, retries,
  File "/home/nathan/Documents/saneora_env/lib/python3.9/site-packages/telegram/vendor/ptb_urllib3/urllib3/connectionpool.py", line 665, in urlopen
    retries = retries.increment(method, url, error=e, _pool=self,
  File "/home/nathan/Documents/saneora_env/lib/python3.9/site-packages/telegram/vendor/ptb_urllib3/urllib3/util/retry.py", line 376, in increment
    raise MaxRetryError(_pool, url, error or ResponseError(cause))
telegram.vendor.ptb_urllib3.urllib3.exceptions.MaxRetryError: HTTPSConnectionPool(host='api.telegram.org', port=443): Max retries exceeded with url: /bot5396659125:AAGCO4gHk2qm0RY2trx7u6pO23OpwAO4hg0/getUpdates (Caused by NewConnectionError('<telegram.vendor.ptb_urllib3.urllib3.connection.VerifiedHTTPSConnection object at 0x7fd5c804a2e0>: Failed to establish a new connection: [Errno -3] Temporary failure in name resolution'))

The above exception was the direct cause of the following exception:

Traceback (most recent call last):
  File "/home/nathan/Documents/saneora_env/lib/python3.9/site-packages/telegram/ext/updater.py", line 646, in _network_loop_retry
    if not action_cb():
  File "/home/nathan/Documents/saneora_env/lib/python3.9/site-packages/telegram/ext/updater.py", line 597, in polling_action_cb
    updates = self.bot.get_updates(
  File "/home/nathan/Documents/saneora_env/lib/python3.9/site-packages/telegram/ext/extbot.py", line 224, in get_updates
    updates = super().get_updates(
  File "/home/nathan/Documents/saneora_env/lib/python3.9/site-packages/telegram/bot.py", line 130, in decorator
    result = func(*args, **kwargs)
  File "/home/nathan/Documents/saneora_env/lib/python3.9/site-packages/telegram/bot.py", line 3054, in get_updates
    self._post(
  File "/home/nathan/Documents/saneora_env/lib/python3.9/site-packages/telegram/bot.py", line 295, in _post
    return self.request.post(
  File "/home/nathan/Documents/saneora_env/lib/python3.9/site-packages/telegram/utils/request.py", line 361, in post
    result = self._request_wrapper(
  File "/home/nathan/Documents/saneora_env/lib/python3.9/site-packages/telegram/utils/request.py", line 265, in _request_wrapper
    raise NetworkError(f'urllib3 HTTPError {error}') from error
telegram.error.NetworkError: urllib3 HTTPError HTTPSConnectionPool(host='api.telegram.org', port=443): Max retries exceeded with url: /bot5396659125:AAGCO4gHk2qm0RY2trx7u6pO23OpwAO4hg0/getUpdates (Caused by NewConnectionError('<telegram.vendor.ptb_urllib3.urllib3.connection.VerifiedHTTPSConnection object at 0x7fd5c804a2e0>: Failed to establish a new connection: [Errno -3] Temporary failure in name resolution'))
Error while getting Updates: urllib3 HTTPError HTTPSConnectionPool(host='api.telegram.org', port=443): Max retries exceeded with url: /bot5396659125:AAGCO4gHk2qm0RY2trx7u6pO23OpwAO4hg0/getUpdates (Caused by NewConnectionError('<telegram.vendor.ptb_urllib3.urllib3.connection.VerifiedHTTPSConnection object at 0x7fd5c993b6d0>: Failed to establish a new connection: [Errno -3] Temporary failure in name resolution'))
No error handlers are registered, logging exception.
Traceback (most recent call last):
  File "/home/nathan/Documents/saneora_env/lib/python3.9/site-packages/telegram/vendor/ptb_urllib3/urllib3/connection.py", line 140, in _new_conn
    conn = connection.create_connection(
  File "/home/nathan/Documents/saneora_env/lib/python3.9/site-packages/telegram/vendor/ptb_urllib3/urllib3/util/connection.py", line 60, in create_connection
    for res in socket.getaddrinfo(host, port, family, socket.SOCK_STREAM):
  File "/usr/lib/python3.9/socket.py", line 953, in getaddrinfo
    for res in _socket.getaddrinfo(host, port, family, type, proto, flags):
socket.gaierror: [Errno -3] Temporary failure in name resolution

During handling of the above exception, another exception occurred:

Traceback (most recent call last):
  File "/home/nathan/Documents/saneora_env/lib/python3.9/site-packages/telegram/vendor/ptb_urllib3/urllib3/connectionpool.py", line 614, in urlopen
    httplib_response = self._make_request(conn, method, url,
  File "/home/nathan/Documents/saneora_env/lib/python3.9/site-packages/telegram/vendor/ptb_urllib3/urllib3/connectionpool.py", line 360, in _make_request
    self._validate_conn(conn)
  File "/home/nathan/Documents/saneora_env/lib/python3.9/site-packages/telegram/vendor/ptb_urllib3/urllib3/connectionpool.py", line 857, in _validate_conn
    super(HTTPSConnectionPool, self)._validate_conn(conn)
  File "/home/nathan/Documents/saneora_env/lib/python3.9/site-packages/telegram/vendor/ptb_urllib3/urllib3/connectionpool.py", line 289, in _validate_conn
    conn.connect()
  File "/home/nathan/Documents/saneora_env/lib/python3.9/site-packages/telegram/vendor/ptb_urllib3/urllib3/connection.py", line 284, in connect
    conn = self._new_conn()
  File "/home/nathan/Documents/saneora_env/lib/python3.9/site-packages/telegram/vendor/ptb_urllib3/urllib3/connection.py", line 149, in _new_conn
    raise NewConnectionError(
telegram.vendor.ptb_urllib3.urllib3.exceptions.NewConnectionError: <telegram.vendor.ptb_urllib3.urllib3.connection.VerifiedHTTPSConnection object at 0x7fd5c993b6d0>: Failed to establish a new connection: [Errno -3] Temporary failure in name resolution

During handling of the above exception, another exception occurred:

Traceback (most recent call last):
  File "/home/nathan/Documents/saneora_env/lib/python3.9/site-packages/telegram/utils/request.py", line 259, in _request_wrapper
    resp = self._con_pool.request(*args, **kwargs)
  File "/home/nathan/Documents/saneora_env/lib/python3.9/site-packages/telegram/vendor/ptb_urllib3/urllib3/request.py", line 68, in request
    return self.request_encode_body(method, url, fields=fields,
  File "/home/nathan/Documents/saneora_env/lib/python3.9/site-packages/telegram/vendor/ptb_urllib3/urllib3/request.py", line 148, in request_encode_body
    return self.urlopen(method, url, **extra_kw)
  File "/home/nathan/Documents/saneora_env/lib/python3.9/site-packages/telegram/vendor/ptb_urllib3/urllib3/poolmanager.py", line 244, in urlopen
    response = conn.urlopen(method, u.request_uri, **kw)
  File "/home/nathan/Documents/saneora_env/lib/python3.9/site-packages/telegram/vendor/ptb_urllib3/urllib3/connectionpool.py", line 691, in urlopen
    return self.urlopen(method, url, body, headers, retries,
  File "/home/nathan/Documents/saneora_env/lib/python3.9/site-packages/telegram/vendor/ptb_urllib3/urllib3/connectionpool.py", line 691, in urlopen
    return self.urlopen(method, url, body, headers, retries,
  File "/home/nathan/Documents/saneora_env/lib/python3.9/site-packages/telegram/vendor/ptb_urllib3/urllib3/connectionpool.py", line 691, in urlopen
    return self.urlopen(method, url, body, headers, retries,
  File "/home/nathan/Documents/saneora_env/lib/python3.9/site-packages/telegram/vendor/ptb_urllib3/urllib3/connectionpool.py", line 665, in urlopen
    retries = retries.increment(method, url, error=e, _pool=self,
  File "/home/nathan/Documents/saneora_env/lib/python3.9/site-packages/telegram/vendor/ptb_urllib3/urllib3/util/retry.py", line 376, in increment
    raise MaxRetryError(_pool, url, error or ResponseError(cause))
telegram.vendor.ptb_urllib3.urllib3.exceptions.MaxRetryError: HTTPSConnectionPool(host='api.telegram.org', port=443): Max retries exceeded with url: /bot5396659125:AAGCO4gHk2qm0RY2trx7u6pO23OpwAO4hg0/getUpdates (Caused by NewConnectionError('<telegram.vendor.ptb_urllib3.urllib3.connection.VerifiedHTTPSConnection object at 0x7fd5c993b6d0>: Failed to establish a new connection: [Errno -3] Temporary failure in name resolution'))

The above exception was the direct cause of the following exception:

Traceback (most recent call last):
  File "/home/nathan/Documents/saneora_env/lib/python3.9/site-packages/telegram/ext/updater.py", line 646, in _network_loop_retry
    if not action_cb():
  File "/home/nathan/Documents/saneora_env/lib/python3.9/site-packages/telegram/ext/updater.py", line 597, in polling_action_cb
    updates = self.bot.get_updates(
  File "/home/nathan/Documents/saneora_env/lib/python3.9/site-packages/telegram/ext/extbot.py", line 224, in get_updates
    updates = super().get_updates(
  File "/home/nathan/Documents/saneora_env/lib/python3.9/site-packages/telegram/bot.py", line 130, in decorator
    result = func(*args, **kwargs)
  File "/home/nathan/Documents/saneora_env/lib/python3.9/site-packages/telegram/bot.py", line 3054, in get_updates
    self._post(
  File "/home/nathan/Documents/saneora_env/lib/python3.9/site-packages/telegram/bot.py", line 295, in _post
    return self.request.post(
  File "/home/nathan/Documents/saneora_env/lib/python3.9/site-packages/telegram/utils/request.py", line 361, in post
    result = self._request_wrapper(
  File "/home/nathan/Documents/saneora_env/lib/python3.9/site-packages/telegram/utils/request.py", line 265, in _request_wrapper
    raise NetworkError(f'urllib3 HTTPError {error}') from error
telegram.error.NetworkError: urllib3 HTTPError HTTPSConnectionPool(host='api.telegram.org', port=443): Max retries exceeded with url: /bot5396659125:AAGCO4gHk2qm0RY2trx7u6pO23OpwAO4hg0/getUpdates (Caused by NewConnectionError('<telegram.vendor.ptb_urllib3.urllib3.connection.VerifiedHTTPSConnection object at 0x7fd5c993b6d0>: Failed to establish a new connection: [Errno -3] Temporary failure in name resolution'))
Error while getting Updates: urllib3 HTTPError HTTPSConnectionPool(host='api.telegram.org', port=443): Max retries exceeded with url: /bot5396659125:AAGCO4gHk2qm0RY2trx7u6pO23OpwAO4hg0/getUpdates (Caused by NewConnectionError('<telegram.vendor.ptb_urllib3.urllib3.connection.VerifiedHTTPSConnection object at 0x7fd5c804a310>: Failed to establish a new connection: [Errno -3] Temporary failure in name resolution'))
No error handlers are registered, logging exception.
Traceback (most recent call last):
  File "/home/nathan/Documents/saneora_env/lib/python3.9/site-packages/telegram/vendor/ptb_urllib3/urllib3/connection.py", line 140, in _new_conn
    conn = connection.create_connection(
  File "/home/nathan/Documents/saneora_env/lib/python3.9/site-packages/telegram/vendor/ptb_urllib3/urllib3/util/connection.py", line 60, in create_connection
    for res in socket.getaddrinfo(host, port, family, socket.SOCK_STREAM):
  File "/usr/lib/python3.9/socket.py", line 953, in getaddrinfo
    for res in _socket.getaddrinfo(host, port, family, type, proto, flags):
socket.gaierror: [Errno -3] Temporary failure in name resolution

During handling of the above exception, another exception occurred:

Traceback (most recent call last):
  File "/home/nathan/Documents/saneora_env/lib/python3.9/site-packages/telegram/vendor/ptb_urllib3/urllib3/connectionpool.py", line 614, in urlopen
    httplib_response = self._make_request(conn, method, url,
  File "/home/nathan/Documents/saneora_env/lib/python3.9/site-packages/telegram/vendor/ptb_urllib3/urllib3/connectionpool.py", line 360, in _make_request
    self._validate_conn(conn)
  File "/home/nathan/Documents/saneora_env/lib/python3.9/site-packages/telegram/vendor/ptb_urllib3/urllib3/connectionpool.py", line 857, in _validate_conn
    super(HTTPSConnectionPool, self)._validate_conn(conn)
  File "/home/nathan/Documents/saneora_env/lib/python3.9/site-packages/telegram/vendor/ptb_urllib3/urllib3/connectionpool.py", line 289, in _validate_conn
    conn.connect()
  File "/home/nathan/Documents/saneora_env/lib/python3.9/site-packages/telegram/vendor/ptb_urllib3/urllib3/connection.py", line 284, in connect
    conn = self._new_conn()
  File "/home/nathan/Documents/saneora_env/lib/python3.9/site-packages/telegram/vendor/ptb_urllib3/urllib3/connection.py", line 149, in _new_conn
    raise NewConnectionError(
telegram.vendor.ptb_urllib3.urllib3.exceptions.NewConnectionError: <telegram.vendor.ptb_urllib3.urllib3.connection.VerifiedHTTPSConnection object at 0x7fd5c804a310>: Failed to establish a new connection: [Errno -3] Temporary failure in name resolution

During handling of the above exception, another exception occurred:

Traceback (most recent call last):
  File "/home/nathan/Documents/saneora_env/lib/python3.9/site-packages/telegram/utils/request.py", line 259, in _request_wrapper
    resp = self._con_pool.request(*args, **kwargs)
  File "/home/nathan/Documents/saneora_env/lib/python3.9/site-packages/telegram/vendor/ptb_urllib3/urllib3/request.py", line 68, in request
    return self.request_encode_body(method, url, fields=fields,
  File "/home/nathan/Documents/saneora_env/lib/python3.9/site-packages/telegram/vendor/ptb_urllib3/urllib3/request.py", line 148, in request_encode_body
    return self.urlopen(method, url, **extra_kw)
  File "/home/nathan/Documents/saneora_env/lib/python3.9/site-packages/telegram/vendor/ptb_urllib3/urllib3/poolmanager.py", line 244, in urlopen
    response = conn.urlopen(method, u.request_uri, **kw)
  File "/home/nathan/Documents/saneora_env/lib/python3.9/site-packages/telegram/vendor/ptb_urllib3/urllib3/connectionpool.py", line 691, in urlopen
    return self.urlopen(method, url, body, headers, retries,
  File "/home/nathan/Documents/saneora_env/lib/python3.9/site-packages/telegram/vendor/ptb_urllib3/urllib3/connectionpool.py", line 691, in urlopen
    return self.urlopen(method, url, body, headers, retries,
  File "/home/nathan/Documents/saneora_env/lib/python3.9/site-packages/telegram/vendor/ptb_urllib3/urllib3/connectionpool.py", line 691, in urlopen
    return self.urlopen(method, url, body, headers, retries,
  File "/home/nathan/Documents/saneora_env/lib/python3.9/site-packages/telegram/vendor/ptb_urllib3/urllib3/connectionpool.py", line 665, in urlopen
    retries = retries.increment(method, url, error=e, _pool=self,
  File "/home/nathan/Documents/saneora_env/lib/python3.9/site-packages/telegram/vendor/ptb_urllib3/urllib3/util/retry.py", line 376, in increment
    raise MaxRetryError(_pool, url, error or ResponseError(cause))
telegram.vendor.ptb_urllib3.urllib3.exceptions.MaxRetryError: HTTPSConnectionPool(host='api.telegram.org', port=443): Max retries exceeded with url: /bot5396659125:AAGCO4gHk2qm0RY2trx7u6pO23OpwAO4hg0/getUpdates (Caused by NewConnectionError('<telegram.vendor.ptb_urllib3.urllib3.connection.VerifiedHTTPSConnection object at 0x7fd5c804a310>: Failed to establish a new connection: [Errno -3] Temporary failure in name resolution'))

The above exception was the direct cause of the following exception:

Traceback (most recent call last):
  File "/home/nathan/Documents/saneora_env/lib/python3.9/site-packages/telegram/ext/updater.py", line 646, in _network_loop_retry
    if not action_cb():
  File "/home/nathan/Documents/saneora_env/lib/python3.9/site-packages/telegram/ext/updater.py", line 597, in polling_action_cb
    updates = self.bot.get_updates(
  File "/home/nathan/Documents/saneora_env/lib/python3.9/site-packages/telegram/ext/extbot.py", line 224, in get_updates
    updates = super().get_updates(
  File "/home/nathan/Documents/saneora_env/lib/python3.9/site-packages/telegram/bot.py", line 130, in decorator
    result = func(*args, **kwargs)
  File "/home/nathan/Documents/saneora_env/lib/python3.9/site-packages/telegram/bot.py", line 3054, in get_updates
    self._post(
  File "/home/nathan/Documents/saneora_env/lib/python3.9/site-packages/telegram/bot.py", line 295, in _post
    return self.request.post(
  File "/home/nathan/Documents/saneora_env/lib/python3.9/site-packages/telegram/utils/request.py", line 361, in post
    result = self._request_wrapper(
  File "/home/nathan/Documents/saneora_env/lib/python3.9/site-packages/telegram/utils/request.py", line 265, in _request_wrapper
    raise NetworkError(f'urllib3 HTTPError {error}') from error
telegram.error.NetworkError: urllib3 HTTPError HTTPSConnectionPool(host='api.telegram.org', port=443): Max retries exceeded with url: /bot5396659125:AAGCO4gHk2qm0RY2trx7u6pO23OpwAO4hg0/getUpdates (Caused by NewConnectionError('<telegram.vendor.ptb_urllib3.urllib3.connection.VerifiedHTTPSConnection object at 0x7fd5c804a310>: Failed to establish a new connection: [Errno -3] Temporary failure in name resolution'))
Error while getting Updates: urllib3 HTTPError HTTPSConnectionPool(host='api.telegram.org', port=443): Max retries exceeded with url: /bot5396659125:AAGCO4gHk2qm0RY2trx7u6pO23OpwAO4hg0/getUpdates (Caused by NewConnectionError('<telegram.vendor.ptb_urllib3.urllib3.connection.VerifiedHTTPSConnection object at 0x7fd5c804a700>: Failed to establish a new connection: [Errno -3] Temporary failure in name resolution'))
No error handlers are registered, logging exception.
Traceback (most recent call last):
  File "/home/nathan/Documents/saneora_env/lib/python3.9/site-packages/telegram/vendor/ptb_urllib3/urllib3/connection.py", line 140, in _new_conn
    conn = connection.create_connection(
  File "/home/nathan/Documents/saneora_env/lib/python3.9/site-packages/telegram/vendor/ptb_urllib3/urllib3/util/connection.py", line 60, in create_connection
    for res in socket.getaddrinfo(host, port, family, socket.SOCK_STREAM):
  File "/usr/lib/python3.9/socket.py", line 953, in getaddrinfo
    for res in _socket.getaddrinfo(host, port, family, type, proto, flags):
socket.gaierror: [Errno -3] Temporary failure in name resolution

During handling of the above exception, another exception occurred:

Traceback (most recent call last):
  File "/home/nathan/Documents/saneora_env/lib/python3.9/site-packages/telegram/vendor/ptb_urllib3/urllib3/connectionpool.py", line 614, in urlopen
    httplib_response = self._make_request(conn, method, url,
  File "/home/nathan/Documents/saneora_env/lib/python3.9/site-packages/telegram/vendor/ptb_urllib3/urllib3/connectionpool.py", line 360, in _make_request
    self._validate_conn(conn)
  File "/home/nathan/Documents/saneora_env/lib/python3.9/site-packages/telegram/vendor/ptb_urllib3/urllib3/connectionpool.py", line 857, in _validate_conn
    super(HTTPSConnectionPool, self)._validate_conn(conn)
  File "/home/nathan/Documents/saneora_env/lib/python3.9/site-packages/telegram/vendor/ptb_urllib3/urllib3/connectionpool.py", line 289, in _validate_conn
    conn.connect()
  File "/home/nathan/Documents/saneora_env/lib/python3.9/site-packages/telegram/vendor/ptb_urllib3/urllib3/connection.py", line 284, in connect
    conn = self._new_conn()
  File "/home/nathan/Documents/saneora_env/lib/python3.9/site-packages/telegram/vendor/ptb_urllib3/urllib3/connection.py", line 149, in _new_conn
    raise NewConnectionError(
telegram.vendor.ptb_urllib3.urllib3.exceptions.NewConnectionError: <telegram.vendor.ptb_urllib3.urllib3.connection.VerifiedHTTPSConnection object at 0x7fd5c804a700>: Failed to establish a new connection: [Errno -3] Temporary failure in name resolution

During handling of the above exception, another exception occurred:

Traceback (most recent call last):
  File "/home/nathan/Documents/saneora_env/lib/python3.9/site-packages/telegram/utils/request.py", line 259, in _request_wrapper
    resp = self._con_pool.request(*args, **kwargs)
  File "/home/nathan/Documents/saneora_env/lib/python3.9/site-packages/telegram/vendor/ptb_urllib3/urllib3/request.py", line 68, in request
    return self.request_encode_body(method, url, fields=fields,
  File "/home/nathan/Documents/saneora_env/lib/python3.9/site-packages/telegram/vendor/ptb_urllib3/urllib3/request.py", line 148, in request_encode_body
    return self.urlopen(method, url, **extra_kw)
  File "/home/nathan/Documents/saneora_env/lib/python3.9/site-packages/telegram/vendor/ptb_urllib3/urllib3/poolmanager.py", line 244, in urlopen
    response = conn.urlopen(method, u.request_uri, **kw)
  File "/home/nathan/Documents/saneora_env/lib/python3.9/site-packages/telegram/vendor/ptb_urllib3/urllib3/connectionpool.py", line 691, in urlopen
    return self.urlopen(method, url, body, headers, retries,
  File "/home/nathan/Documents/saneora_env/lib/python3.9/site-packages/telegram/vendor/ptb_urllib3/urllib3/connectionpool.py", line 691, in urlopen
    return self.urlopen(method, url, body, headers, retries,
  File "/home/nathan/Documents/saneora_env/lib/python3.9/site-packages/telegram/vendor/ptb_urllib3/urllib3/connectionpool.py", line 691, in urlopen
    return self.urlopen(method, url, body, headers, retries,
  File "/home/nathan/Documents/saneora_env/lib/python3.9/site-packages/telegram/vendor/ptb_urllib3/urllib3/connectionpool.py", line 665, in urlopen
    retries = retries.increment(method, url, error=e, _pool=self,
  File "/home/nathan/Documents/saneora_env/lib/python3.9/site-packages/telegram/vendor/ptb_urllib3/urllib3/util/retry.py", line 376, in increment
    raise MaxRetryError(_pool, url, error or ResponseError(cause))
telegram.vendor.ptb_urllib3.urllib3.exceptions.MaxRetryError: HTTPSConnectionPool(host='api.telegram.org', port=443): Max retries exceeded with url: /bot5396659125:AAGCO4gHk2qm0RY2trx7u6pO23OpwAO4hg0/getUpdates (Caused by NewConnectionError('<telegram.vendor.ptb_urllib3.urllib3.connection.VerifiedHTTPSConnection object at 0x7fd5c804a700>: Failed to establish a new connection: [Errno -3] Temporary failure in name resolution'))

The above exception was the direct cause of the following exception:

Traceback (most recent call last):
  File "/home/nathan/Documents/saneora_env/lib/python3.9/site-packages/telegram/ext/updater.py", line 646, in _network_loop_retry
    if not action_cb():
  File "/home/nathan/Documents/saneora_env/lib/python3.9/site-packages/telegram/ext/updater.py", line 597, in polling_action_cb
    updates = self.bot.get_updates(
  File "/home/nathan/Documents/saneora_env/lib/python3.9/site-packages/telegram/ext/extbot.py", line 224, in get_updates
    updates = super().get_updates(
  File "/home/nathan/Documents/saneora_env/lib/python3.9/site-packages/telegram/bot.py", line 130, in decorator
    result = func(*args, **kwargs)
  File "/home/nathan/Documents/saneora_env/lib/python3.9/site-packages/telegram/bot.py", line 3054, in get_updates
    self._post(
  File "/home/nathan/Documents/saneora_env/lib/python3.9/site-packages/telegram/bot.py", line 295, in _post
    return self.request.post(
  File "/home/nathan/Documents/saneora_env/lib/python3.9/site-packages/telegram/utils/request.py", line 361, in post
    result = self._request_wrapper(
  File "/home/nathan/Documents/saneora_env/lib/python3.9/site-packages/telegram/utils/request.py", line 265, in _request_wrapper
    raise NetworkError(f'urllib3 HTTPError {error}') from error
telegram.error.NetworkError: urllib3 HTTPError HTTPSConnectionPool(host='api.telegram.org', port=443): Max retries exceeded with url: /bot5396659125:AAGCO4gHk2qm0RY2trx7u6pO23OpwAO4hg0/getUpdates (Caused by NewConnectionError('<telegram.vendor.ptb_urllib3.urllib3.connection.VerifiedHTTPSConnection object at 0x7fd5c804a700>: Failed to establish a new connection: [Errno -3] Temporary failure in name resolution'))
Error while getting Updates: urllib3 HTTPError HTTPSConnectionPool(host='api.telegram.org', port=443): Max retries exceeded with url: /bot5396659125:AAGCO4gHk2qm0RY2trx7u6pO23OpwAO4hg0/getUpdates (Caused by NewConnectionError('<telegram.vendor.ptb_urllib3.urllib3.connection.VerifiedHTTPSConnection object at 0x7fd5c804ab50>: Failed to establish a new connection: [Errno -3] Temporary failure in name resolution'))
No error handlers are registered, logging exception.
Traceback (most recent call last):
  File "/home/nathan/Documents/saneora_env/lib/python3.9/site-packages/telegram/vendor/ptb_urllib3/urllib3/connection.py", line 140, in _new_conn
    conn = connection.create_connection(
  File "/home/nathan/Documents/saneora_env/lib/python3.9/site-packages/telegram/vendor/ptb_urllib3/urllib3/util/connection.py", line 60, in create_connection
    for res in socket.getaddrinfo(host, port, family, socket.SOCK_STREAM):
  File "/usr/lib/python3.9/socket.py", line 953, in getaddrinfo
    for res in _socket.getaddrinfo(host, port, family, type, proto, flags):
socket.gaierror: [Errno -3] Temporary failure in name resolution

During handling of the above exception, another exception occurred:

Traceback (most recent call last):
  File "/home/nathan/Documents/saneora_env/lib/python3.9/site-packages/telegram/vendor/ptb_urllib3/urllib3/connectionpool.py", line 614, in urlopen
    httplib_response = self._make_request(conn, method, url,
  File "/home/nathan/Documents/saneora_env/lib/python3.9/site-packages/telegram/vendor/ptb_urllib3/urllib3/connectionpool.py", line 360, in _make_request
    self._validate_conn(conn)
  File "/home/nathan/Documents/saneora_env/lib/python3.9/site-packages/telegram/vendor/ptb_urllib3/urllib3/connectionpool.py", line 857, in _validate_conn
    super(HTTPSConnectionPool, self)._validate_conn(conn)
  File "/home/nathan/Documents/saneora_env/lib/python3.9/site-packages/telegram/vendor/ptb_urllib3/urllib3/connectionpool.py", line 289, in _validate_conn
    conn.connect()
  File "/home/nathan/Documents/saneora_env/lib/python3.9/site-packages/telegram/vendor/ptb_urllib3/urllib3/connection.py", line 284, in connect
    conn = self._new_conn()
  File "/home/nathan/Documents/saneora_env/lib/python3.9/site-packages/telegram/vendor/ptb_urllib3/urllib3/connection.py", line 149, in _new_conn
    raise NewConnectionError(
telegram.vendor.ptb_urllib3.urllib3.exceptions.NewConnectionError: <telegram.vendor.ptb_urllib3.urllib3.connection.VerifiedHTTPSConnection object at 0x7fd5c804ab50>: Failed to establish a new connection: [Errno -3] Temporary failure in name resolution

During handling of the above exception, another exception occurred:

Traceback (most recent call last):
  File "/home/nathan/Documents/saneora_env/lib/python3.9/site-packages/telegram/utils/request.py", line 259, in _request_wrapper
    resp = self._con_pool.request(*args, **kwargs)
  File "/home/nathan/Documents/saneora_env/lib/python3.9/site-packages/telegram/vendor/ptb_urllib3/urllib3/request.py", line 68, in request
    return self.request_encode_body(method, url, fields=fields,
  File "/home/nathan/Documents/saneora_env/lib/python3.9/site-packages/telegram/vendor/ptb_urllib3/urllib3/request.py", line 148, in request_encode_body
    return self.urlopen(method, url, **extra_kw)
  File "/home/nathan/Documents/saneora_env/lib/python3.9/site-packages/telegram/vendor/ptb_urllib3/urllib3/poolmanager.py", line 244, in urlopen
    response = conn.urlopen(method, u.request_uri, **kw)
  File "/home/nathan/Documents/saneora_env/lib/python3.9/site-packages/telegram/vendor/ptb_urllib3/urllib3/connectionpool.py", line 691, in urlopen
    return self.urlopen(method, url, body, headers, retries,
  File "/home/nathan/Documents/saneora_env/lib/python3.9/site-packages/telegram/vendor/ptb_urllib3/urllib3/connectionpool.py", line 691, in urlopen
    return self.urlopen(method, url, body, headers, retries,
  File "/home/nathan/Documents/saneora_env/lib/python3.9/site-packages/telegram/vendor/ptb_urllib3/urllib3/connectionpool.py", line 691, in urlopen
    return self.urlopen(method, url, body, headers, retries,
  File "/home/nathan/Documents/saneora_env/lib/python3.9/site-packages/telegram/vendor/ptb_urllib3/urllib3/connectionpool.py", line 665, in urlopen
    retries = retries.increment(method, url, error=e, _pool=self,
  File "/home/nathan/Documents/saneora_env/lib/python3.9/site-packages/telegram/vendor/ptb_urllib3/urllib3/util/retry.py", line 376, in increment
    raise MaxRetryError(_pool, url, error or ResponseError(cause))
telegram.vendor.ptb_urllib3.urllib3.exceptions.MaxRetryError: HTTPSConnectionPool(host='api.telegram.org', port=443): Max retries exceeded with url: /bot5396659125:AAGCO4gHk2qm0RY2trx7u6pO23OpwAO4hg0/getUpdates (Caused by NewConnectionError('<telegram.vendor.ptb_urllib3.urllib3.connection.VerifiedHTTPSConnection object at 0x7fd5c804ab50>: Failed to establish a new connection: [Errno -3] Temporary failure in name resolution'))

The above exception was the direct cause of the following exception:

Traceback (most recent call last):
  File "/home/nathan/Documents/saneora_env/lib/python3.9/site-packages/telegram/ext/updater.py", line 646, in _network_loop_retry
    if not action_cb():
  File "/home/nathan/Documents/saneora_env/lib/python3.9/site-packages/telegram/ext/updater.py", line 597, in polling_action_cb
    updates = self.bot.get_updates(
  File "/home/nathan/Documents/saneora_env/lib/python3.9/site-packages/telegram/ext/extbot.py", line 224, in get_updates
    updates = super().get_updates(
  File "/home/nathan/Documents/saneora_env/lib/python3.9/site-packages/telegram/bot.py", line 130, in decorator
    result = func(*args, **kwargs)
  File "/home/nathan/Documents/saneora_env/lib/python3.9/site-packages/telegram/bot.py", line 3054, in get_updates
    self._post(
  File "/home/nathan/Documents/saneora_env/lib/python3.9/site-packages/telegram/bot.py", line 295, in _post
    return self.request.post(
  File "/home/nathan/Documents/saneora_env/lib/python3.9/site-packages/telegram/utils/request.py", line 361, in post
    result = self._request_wrapper(
  File "/home/nathan/Documents/saneora_env/lib/python3.9/site-packages/telegram/utils/request.py", line 265, in _request_wrapper
    raise NetworkError(f'urllib3 HTTPError {error}') from error
telegram.error.NetworkError: urllib3 HTTPError HTTPSConnectionPool(host='api.telegram.org', port=443): Max retries exceeded with url: /bot5396659125:AAGCO4gHk2qm0RY2trx7u6pO23OpwAO4hg0/getUpdates (Caused by NewConnectionError('<telegram.vendor.ptb_urllib3.urllib3.connection.VerifiedHTTPSConnection object at 0x7fd5c804ab50>: Failed to establish a new connection: [Errno -3] Temporary failure in name resolution'))
